<?xml version="1.0" encoding="UTF-8"?>
<!-- Generated by org.testng.reporters.JUnitReportReporter -->
<testsuite skipped="0" hostname="Sanjeet3149591" name="com.nagarro.testCases.TestcasesForOrderPlacedInPresentNFuture" tests="16" failures="1" timestamp="18 Dec 2018 12:39:45 GMT" time="17.644" errors="0">
  <testcase name="testcase_Verify_PlaceNewOrder" time="4.890" classname="com.nagarro.testCases.TestcasesForOrderPlacedInPresentNFuture"/>
  <testcase name="testcases_Verify__CancelOrder" time="0.427" classname="com.nagarro.testCases.TestcasesForOrderPlacedInPresentNFuture"/>
  <testcase name="testcases_Verify__FetchTheOrderDetails" time="0.585" classname="com.nagarro.testCases.TestcasesForOrderPlacedInPresentNFuture"/>
  <testcase name="testcases_Verify__TakeTheOrderDetails" time="0.117" classname="com.nagarro.testCases.TestcasesForOrderPlacedInPresentNFuture"/>
  <testcase name="testcases_Verify__CompleteTheOrderDetails" time="0.111" classname="com.nagarro.testCases.TestcasesForOrderPlacedInPresentNFuture"/>
  <testcase name="testcases_Verify__TakeTheOngoingOrder" time="0.571" classname="com.nagarro.testCases.TestcasesForOrderPlacedInPresentNFuture"/>
  <testcase name="testcases_Verify__TakeTheCompletedOrder" time="0.853" classname="com.nagarro.testCases.TestcasesForOrderPlacedInPresentNFuture"/>
  <testcase name="testcases_Verify__TakeTheCancelledOrder" time="1.191" classname="com.nagarro.testCases.TestcasesForOrderPlacedInPresentNFuture"/>
  <testcase name="testcases_Verify__CompleteTheNewOrder" time="0.496" classname="com.nagarro.testCases.TestcasesForOrderPlacedInPresentNFuture"/>
  <testcase name="testcases_Verify__CompleteTheOrderAfterCompleted" time="3.817" classname="com.nagarro.testCases.TestcasesForOrderPlacedInPresentNFuture"/>
  <testcase name="testcases_Verify__CancelTheOrderAfterCompleted" time="0.769" classname="com.nagarro.testCases.TestcasesForOrderPlacedInPresentNFuture"/>
  <testcase name="testcases_Verify__TakeTheOrderAfterCompleted" time="0.736" classname="com.nagarro.testCases.TestcasesForOrderPlacedInPresentNFuture"/>
  <testcase name="testcases_Verify__CancelTheOrderAfterCancel" time="1.087" classname="com.nagarro.testCases.TestcasesForOrderPlacedInPresentNFuture">
    <failure type="java.lang.AssertionError" message="Status code is not 422 expected [422] but found [200]">
      <![CDATA[java.lang.AssertionError: Status code is not 422 expected [422] but found [200]
at org.testng.Assert.fail(Assert.java:96)
at org.testng.Assert.failNotEquals(Assert.java:776)
at org.testng.Assert.assertEqualsImpl(Assert.java:137)
at org.testng.Assert.assertEquals(Assert.java:118)
at org.testng.Assert.assertEquals(Assert.java:652)
at com.nagarro.util.CommonUtility.Verify_ResponseCode422(CommonUtility.java:210)
at com.nagarro.testCases.TestcasesForOrderPlacedInPresentNFuture.testcases_Verify__CancelTheOrderAfterCancel(TestcasesForOrderPlacedInPresentNFuture.java:323)
at sun.reflect.NativeMethodAccessorImpl.invoke0(Native Method)
at sun.reflect.NativeMethodAccessorImpl.invoke(NativeMethodAccessorImpl.java:62)
at sun.reflect.DelegatingMethodAccessorImpl.invoke(DelegatingMethodAccessorImpl.java:43)
at java.lang.reflect.Method.invoke(Method.java:498)
at org.testng.internal.MethodInvocationHelper.invokeMethod(MethodInvocationHelper.java:124)
at org.testng.internal.Invoker.invokeMethod(Invoker.java:583)
at org.testng.internal.Invoker.invokeTestMethod(Invoker.java:719)
at org.testng.internal.Invoker.invokeTestMethods(Invoker.java:989)
at org.testng.internal.TestMethodWorker.invokeTestMethods(TestMethodWorker.java:125)
at org.testng.internal.TestMethodWorker.run(TestMethodWorker.java:109)
at org.testng.TestRunner.privateRun(TestRunner.java:648)
at org.testng.TestRunner.run(TestRunner.java:505)
at org.testng.SuiteRunner.runTest(SuiteRunner.java:455)
at org.testng.SuiteRunner.runSequentially(SuiteRunner.java:450)
at org.testng.SuiteRunner.privateRun(SuiteRunner.java:415)
at org.testng.SuiteRunner.run(SuiteRunner.java:364)
at org.testng.SuiteRunnerWorker.runSuite(SuiteRunnerWorker.java:52)
at org.testng.SuiteRunnerWorker.run(SuiteRunnerWorker.java:84)
at org.testng.TestNG.runSuitesSequentially(TestNG.java:1208)
at org.testng.TestNG.runSuitesLocally(TestNG.java:1137)
at org.testng.TestNG.runSuites(TestNG.java:1049)
at org.testng.TestNG.run(TestNG.java:1017)
at org.testng.remote.AbstractRemoteTestNG.run(AbstractRemoteTestNG.java:114)
at org.testng.remote.RemoteTestNG.initAndRun(RemoteTestNG.java:251)
at org.testng.remote.RemoteTestNG.main(RemoteTestNG.java:77)
]]>
    </failure>
  </testcase> <!-- testcases_Verify__CancelTheOrderAfterCancel -->
  <testcase name="testcases_Verify__CompleteTheOrderAfterCancel" time="0.911" classname="com.nagarro.testCases.TestcasesForOrderPlacedInPresentNFuture"/>
  <testcase name="testcases_Verify__TakeTheOrderAfterCancelled" time="0.998" classname="com.nagarro.testCases.TestcasesForOrderPlacedInPresentNFuture"/>
  <testcase name="testcases_Verify__FetchTheOrderDetailsNotCreated" time="0.085" classname="com.nagarro.testCases.TestcasesForOrderPlacedInPresentNFuture"/>
</testsuite> <!-- com.nagarro.testCases.TestcasesForOrderPlacedInPresentNFuture -->
